<robot name = "robot">
    <link name="Body1.0.0">
        <inertial>
            <origin xyz="0 0 3" rpy="0 0 0"/>
            <mass value="1" />
            <inertia ixx="100" ixy="0" ixz="0" iyy="100" iyz="0" izz="100" />
        </inertial>
        <visual>
            <origin xyz="0 0 3" rpy="0 0 0"/>
            <geometry>
                <box size="1.2272046000463313 0.8519242532142662 0.9130884813200549" />
            </geometry>
            <material name="Green">
                <color rgba="0.0 1.0 0.0 1.0"/>
            </material>
        </visual>
        <collision>
            <origin xyz="0 0 3" rpy="0 0 0"/>
            <geometry>
                <box size="1.2272046000463313 0.8519242532142662 0.9130884813200549" />
            </geometry>
        </collision>
    </link>
    <link name="Body2.0.0">
        <inertial>
            <origin xyz="0.5239680129994124 0 0" rpy="0 0 0"/>
            <mass value="1" />
            <inertia ixx="100" ixy="0" ixz="0" iyy="100" iyz="0" izz="100" />
        </inertial>
        <visual>
            <origin xyz="0.5239680129994124 0 0" rpy="0 0 0"/>
            <geometry>
                <box size="1.0479360259988248 1.0378610294513226 0.9057304142217791" />
            </geometry>
            <material name="Blue">
                <color rgba="0.0 0.0 1.0 1.0"/>
            </material>
        </visual>
        <collision>
            <origin xyz="0.5239680129994124 0 0" rpy="0 0 0"/>
            <geometry>
                <box size="1.0479360259988248 1.0378610294513226 0.9057304142217791" />
            </geometry>
        </collision>
    </link>
    <link name="Body1.1.0">
        <inertial>
            <origin xyz="0 -0.2847670351360405 0" rpy="0 0 0"/>
            <mass value="1" />
            <inertia ixx="100" ixy="0" ixz="0" iyy="100" iyz="0" izz="100" />
        </inertial>
        <visual>
            <origin xyz="0 -0.2847670351360405 0" rpy="0 0 0"/>
            <geometry>
                <box size="0.4881766043496675 0.569534070272081 0.537654106005881" />
            </geometry>
            <material name="Blue">
                <color rgba="0.0 0.0 1.0 1.0"/>
            </material>
        </visual>
        <collision>
            <origin xyz="0 -0.2847670351360405 0" rpy="0 0 0"/>
            <geometry>
                <box size="0.4881766043496675 0.569534070272081 0.537654106005881" />
            </geometry>
        </collision>
    </link>
    <link name="Body1.1.1">
        <inertial>
            <origin xyz="0 0 -0.2987420901109016" rpy="0 0 0"/>
            <mass value="1" />
            <inertia ixx="100" ixy="0" ixz="0" iyy="100" iyz="0" izz="100" />
        </inertial>
        <visual>
            <origin xyz="0 0 -0.2987420901109016" rpy="0 0 0"/>
            <geometry>
                <box size="0.32581118817644306 0.7129177358865038 0.5974841802218032" />
            </geometry>
            <material name="Green">
                <color rgba="0.0 1.0 0.0 1.0"/>
            </material>
        </visual>
        <collision>
            <origin xyz="0 0 -0.2987420901109016" rpy="0 0 0"/>
            <geometry>
                <box size="0.32581118817644306 0.7129177358865038 0.5974841802218032" />
            </geometry>
        </collision>
    </link>
    <link name="Body1.1.2">
        <inertial>
            <origin xyz="0 -0.3643742680383838 0" rpy="0 0 0"/>
            <mass value="1" />
            <inertia ixx="100" ixy="0" ixz="0" iyy="100" iyz="0" izz="100" />
        </inertial>
        <visual>
            <origin xyz="0 -0.3643742680383838 0" rpy="0 0 0"/>
            <geometry>
                <box size="0.3296999698811406 0.7287485360767676 0.5106972573348649" />
            </geometry>
            <material name="Blue">
                <color rgba="0.0 0.0 1.0 1.0"/>
            </material>
        </visual>
        <collision>
            <origin xyz="0 -0.3643742680383838 0" rpy="0 0 0"/>
            <geometry>
                <box size="0.3296999698811406 0.7287485360767676 0.5106972573348649" />
            </geometry>
        </collision>
    </link>
    <link name="Body1.1.3">
        <inertial>
            <origin xyz="0 -0.30470598101645074 0" rpy="0 0 0"/>
            <mass value="1" />
            <inertia ixx="100" ixy="0" ixz="0" iyy="100" iyz="0" izz="100" />
        </inertial>
        <visual>
            <origin xyz="0 -0.30470598101645074 0" rpy="0 0 0"/>
            <geometry>
                <box size="0.4863745443327334 0.6094119620329015 0.7197032000638705" />
            </geometry>
            <material name="Green">
                <color rgba="0.0 1.0 0.0 1.0"/>
            </material>
        </visual>
        <collision>
            <origin xyz="0 -0.30470598101645074 0" rpy="0 0 0"/>
            <geometry>
                <box size="0.4863745443327334 0.6094119620329015 0.7197032000638705" />
            </geometry>
        </collision>
    </link>
    <link name="Body1.2.0">
        <inertial>
            <origin xyz="0 0.32522719274630707 0" rpy="0 0 0"/>
            <mass value="1" />
            <inertia ixx="100" ixy="0" ixz="0" iyy="100" iyz="0" izz="100" />
        </inertial>
        <visual>
            <origin xyz="0 0.32522719274630707 0" rpy="0 0 0"/>
            <geometry>
                <box size="0.44748170200037196 0.6504543854926141 0.6111552640126902" />
            </geometry>
            <material name="Blue">
                <color rgba="0.0 0.0 1.0 1.0"/>
            </material>
        </visual>
        <collision>
            <origin xyz="0 0.32522719274630707 0" rpy="0 0 0"/>
            <geometry>
                <box size="0.44748170200037196 0.6504543854926141 0.6111552640126902" />
            </geometry>
        </collision>
    </link>
    <link name="Body1.2.1">
        <inertial>
            <origin xyz="0 0.1493635774327193 0" rpy="0 0 0"/>
            <mass value="1" />
            <inertia ixx="100" ixy="0" ixz="0" iyy="100" iyz="0" izz="100" />
        </inertial>
        <visual>
            <origin xyz="0 0.1493635774327193 0" rpy="0 0 0"/>
            <geometry>
                <box size="0.6894333301690208 0.2987271548654386 0.5339922150501673" />
            </geometry>
            <material name="Blue">
                <color rgba="0.0 0.0 1.0 1.0"/>
            </material>
        </visual>
        <collision>
            <origin xyz="0 0.1493635774327193 0" rpy="0 0 0"/>
            <geometry>
                <box size="0.6894333301690208 0.2987271548654386 0.5339922150501673" />
            </geometry>
        </collision>
    </link>
    <link name="Body1.2.2">
        <inertial>
            <origin xyz="0 0.23404046665685732 0" rpy="0 0 0"/>
            <mass value="1" />
            <inertia ixx="100" ixy="0" ixz="0" iyy="100" iyz="0" izz="100" />
        </inertial>
        <visual>
            <origin xyz="0 0.23404046665685732 0" rpy="0 0 0"/>
            <geometry>
                <box size="0.7327400694491015 0.46808093331371464 0.656662072716701" />
            </geometry>
            <material name="Green">
                <color rgba="0.0 1.0 0.0 1.0"/>
            </material>
        </visual>
        <collision>
            <origin xyz="0 0.23404046665685732 0" rpy="0 0 0"/>
            <geometry>
                <box size="0.7327400694491015 0.46808093331371464 0.656662072716701" />
            </geometry>
        </collision>
    </link>
    <link name="Body1.2.3">
        <inertial>
            <origin xyz="0 0.22146656471122564 0" rpy="0 0 0"/>
            <mass value="1" />
            <inertia ixx="100" ixy="0" ixz="0" iyy="100" iyz="0" izz="100" />
        </inertial>
        <visual>
            <origin xyz="0 0.22146656471122564 0" rpy="0 0 0"/>
            <geometry>
                <box size="0.5036214919145298 0.4429331294224513 0.587727622192545" />
            </geometry>
            <material name="Green">
                <color rgba="0.0 1.0 0.0 1.0"/>
            </material>
        </visual>
        <collision>
            <origin xyz="0 0.22146656471122564 0" rpy="0 0 0"/>
            <geometry>
                <box size="0.5036214919145298 0.4429331294224513 0.587727622192545" />
            </geometry>
        </collision>
    </link>
    <link name="Body2.1.0">
        <inertial>
            <origin xyz="0 -0.35105044271194374 0" rpy="0 0 0"/>
            <mass value="1" />
            <inertia ixx="100" ixy="0" ixz="0" iyy="100" iyz="0" izz="100" />
        </inertial>
        <visual>
            <origin xyz="0 -0.35105044271194374 0" rpy="0 0 0"/>
            <geometry>
                <box size="0.5421258964850995 0.7021008854238875 0.6704955341587416" />
            </geometry>
            <material name="Green">
                <color rgba="0.0 1.0 0.0 1.0"/>
            </material>
        </visual>
        <collision>
            <origin xyz="0 -0.35105044271194374 0" rpy="0 0 0"/>
            <geometry>
                <box size="0.5421258964850995 0.7021008854238875 0.6704955341587416" />
            </geometry>
        </collision>
    </link>
    <link name="Body2.2.0">
        <inertial>
            <origin xyz="0 0.3727474112172038 0" rpy="0 0 0"/>
            <mass value="1" />
            <inertia ixx="100" ixy="0" ixz="0" iyy="100" iyz="0" izz="100" />
        </inertial>
        <visual>
            <origin xyz="0 0.3727474112172038 0" rpy="0 0 0"/>
            <geometry>
                <box size="0.6782002831983778 0.7454948224344076 0.6678183855406296" />
            </geometry>
            <material name="Green">
                <color rgba="0.0 1.0 0.0 1.0"/>
            </material>
        </visual>
        <collision>
            <origin xyz="0 0.3727474112172038 0" rpy="0 0 0"/>
            <geometry>
                <box size="0.6782002831983778 0.7454948224344076 0.6678183855406296" />
            </geometry>
        </collision>
    </link>
    <link name="Body2.2.1">
        <inertial>
            <origin xyz="0 0 -0.31772074280744045" rpy="0 0 0"/>
            <mass value="1" />
            <inertia ixx="100" ixy="0" ixz="0" iyy="100" iyz="0" izz="100" />
        </inertial>
        <visual>
            <origin xyz="0 0 -0.31772074280744045" rpy="0 0 0"/>
            <geometry>
                <box size="0.5993079351657538 0.41319514425334686 0.6354414856148809" />
            </geometry>
            <material name="Blue">
                <color rgba="0.0 0.0 1.0 1.0"/>
            </material>
        </visual>
        <collision>
            <origin xyz="0 0 -0.31772074280744045" rpy="0 0 0"/>
            <geometry>
                <box size="0.5993079351657538 0.41319514425334686 0.6354414856148809" />
            </geometry>
        </collision>
    </link>
    <joint name="Body1.0.0_Body2.0.0" type="revolute">
       <parent link="Body1.0.0"/>
       <child  link="Body2.0.0"/>
       <origin rpy="0 0 0" xyz="0.6136023000231656 0 3" />
       <axis xyz="0 1 0"/>
       <limit effort="0.0" lower="-3.14159" upper="3.14159" velocity="0.0"/>
    </joint>
    <joint name="Body1.0.0_Body1.1.0" type="revolute">
       <parent link="Body1.0.0"/>
       <child  link="Body1.1.0"/>
       <origin rpy="0 0 0" xyz="0 -0.4259621266071331 3" />
       <axis xyz="0 0 1"/>
       <limit effort="0.0" lower="-3.14159" upper="3.14159" velocity="0.0"/>
    </joint>
    <joint name="Body1.1.0_Body1.1.1" type="revolute">
       <parent link="Body1.1.0"/>
       <child  link="Body1.1.1"/>
       <origin rpy="0 0 0" xyz="0 -0.2847670351360405 -0.2688270530029405" />
       <axis xyz="1 0 0"/>
       <limit effort="0.0" lower="-3.14159" upper="3.14159" velocity="0.0"/>
    </joint>
    <joint name="Body1.1.1_Body1.1.2" type="revolute">
       <parent link="Body1.1.1"/>
       <child  link="Body1.1.2"/>
       <origin rpy="0 0 0" xyz="0 -0.3564588679432519 -0.2987420901109016" />
       <axis xyz="1 0 0"/>
       <limit effort="0.0" lower="-3.14159" upper="3.14159" velocity="0.0"/>
    </joint>
    <joint name="Body1.1.2_Body1.1.3" type="revolute">
       <parent link="Body1.1.2"/>
       <child  link="Body1.1.3"/>
       <origin rpy="0 0 0" xyz="0 -0.7287485360767676 0" />
       <axis xyz="0 0 1"/>
       <limit effort="0.0" lower="-3.14159" upper="3.14159" velocity="0.0"/>
    </joint>
    <joint name="Body1.0.0_Body1.2.0" type="revolute">
       <parent link="Body1.0.0"/>
       <child  link="Body1.2.0"/>
       <origin rpy="0 0 0" xyz="0 0.4259621266071331 3" />
       <axis xyz="1 0 0"/>
       <limit effort="0.0" lower="-3.14159" upper="3.14159" velocity="0.0"/>
    </joint>
    <joint name="Body1.2.0_Body1.2.1" type="revolute">
       <parent link="Body1.2.0"/>
       <child  link="Body1.2.1"/>
       <origin rpy="0 0 0" xyz="0 0.6504543854926141 0" />
       <axis xyz="0 1 0"/>
       <limit effort="0.0" lower="-3.14159" upper="3.14159" velocity="0.0"/>
    </joint>
    <joint name="Body1.2.1_Body1.2.2" type="revolute">
       <parent link="Body1.2.1"/>
       <child  link="Body1.2.2"/>
       <origin rpy="0 0 0" xyz="0 0.2987271548654386 0" />
       <axis xyz="0 1 0"/>
       <limit effort="0.0" lower="-3.14159" upper="3.14159" velocity="0.0"/>
    </joint>
    <joint name="Body1.2.2_Body1.2.3" type="revolute">
       <parent link="Body1.2.2"/>
       <child  link="Body1.2.3"/>
       <origin rpy="0 0 0" xyz="0 0.46808093331371464 0" />
       <axis xyz="1 0 0"/>
       <limit effort="0.0" lower="-3.14159" upper="3.14159" velocity="0.0"/>
    </joint>
    <joint name="Body2.0.0_Body2.1.0" type="revolute">
       <parent link="Body2.0.0"/>
       <child  link="Body2.1.0"/>
       <origin rpy="0 0 0" xyz="0.5239680129994124 -0.5189305147256613 0" />
       <axis xyz="0 0 1"/>
       <limit effort="0.0" lower="-3.14159" upper="3.14159" velocity="0.0"/>
    </joint>
    <joint name="Body2.0.0_Body2.2.0" type="revolute">
       <parent link="Body2.0.0"/>
       <child  link="Body2.2.0"/>
       <origin rpy="0 0 0" xyz="0.5239680129994124 0.5189305147256613 0" />
       <axis xyz="1 0 0"/>
       <limit effort="0.0" lower="-3.14159" upper="3.14159" velocity="0.0"/>
    </joint>
    <joint name="Body2.2.0_Body2.2.1" type="revolute">
       <parent link="Body2.2.0"/>
       <child  link="Body2.2.1"/>
       <origin rpy="0 0 0" xyz="0 0.3727474112172038 -0.3339091927703148" />
       <axis xyz="0 1 0"/>
       <limit effort="0.0" lower="-3.14159" upper="3.14159" velocity="0.0"/>
    </joint>
</robot>