<robot name = "robot">
    <link name="Body1.0.0">
        <inertial>
            <origin xyz="0 0 3" rpy="0 0 0"/>
            <mass value="1" />
            <inertia ixx="100" ixy="0" ixz="0" iyy="100" iyz="0" izz="100" />
        </inertial>
        <visual>
            <origin xyz="0 0 3" rpy="0 0 0"/>
            <geometry>
                <box size="1.076475245067361 0.8180601173796719 0.9413855105189446" />
            </geometry>
            <material name="Blue">
                <color rgba="0.0 0.0 1.0 1.0"/>
            </material>
        </visual>
        <collision>
            <origin xyz="0 0 3" rpy="0 0 0"/>
            <geometry>
                <box size="1.076475245067361 0.8180601173796719 0.9413855105189446" />
            </geometry>
        </collision>
    </link>
    <link name="Body2.0.0">
        <inertial>
            <origin xyz="0.5155489561854842 0 0" rpy="0 0 0"/>
            <mass value="1" />
            <inertia ixx="100" ixy="0" ixz="0" iyy="100" iyz="0" izz="100" />
        </inertial>
        <visual>
            <origin xyz="0.5155489561854842 0 0" rpy="0 0 0"/>
            <geometry>
                <box size="1.0310979123709685 1.0150079786534172 1.1241803925324323" />
            </geometry>
            <material name="Green">
                <color rgba="0.0 1.0 0.0 1.0"/>
            </material>
        </visual>
        <collision>
            <origin xyz="0.5155489561854842 0 0" rpy="0 0 0"/>
            <geometry>
                <box size="1.0310979123709685 1.0150079786534172 1.1241803925324323" />
            </geometry>
        </collision>
    </link>
    <link name="Body3.0.0">
        <inertial>
            <origin xyz="0.6204352684267431 0 0" rpy="0 0 0"/>
            <mass value="1" />
            <inertia ixx="100" ixy="0" ixz="0" iyy="100" iyz="0" izz="100" />
        </inertial>
        <visual>
            <origin xyz="0.6204352684267431 0 0" rpy="0 0 0"/>
            <geometry>
                <box size="1.2408705368534863 1.2089287282432242 0.7366276913777693" />
            </geometry>
            <material name="Green">
                <color rgba="0.0 1.0 0.0 1.0"/>
            </material>
        </visual>
        <collision>
            <origin xyz="0.6204352684267431 0 0" rpy="0 0 0"/>
            <geometry>
                <box size="1.2408705368534863 1.2089287282432242 0.7366276913777693" />
            </geometry>
        </collision>
    </link>
    <link name="Body4.0.0">
        <inertial>
            <origin xyz="0.5685982130083045 0 0" rpy="0 0 0"/>
            <mass value="1" />
            <inertia ixx="100" ixy="0" ixz="0" iyy="100" iyz="0" izz="100" />
        </inertial>
        <visual>
            <origin xyz="0.5685982130083045 0 0" rpy="0 0 0"/>
            <geometry>
                <box size="1.137196426016609 0.8853071898374392 0.8934889422952241" />
            </geometry>
            <material name="Green">
                <color rgba="0.0 1.0 0.0 1.0"/>
            </material>
        </visual>
        <collision>
            <origin xyz="0.5685982130083045 0 0" rpy="0 0 0"/>
            <geometry>
                <box size="1.137196426016609 0.8853071898374392 0.8934889422952241" />
            </geometry>
        </collision>
    </link>
    <link name="Body1.2.0">
        <inertial>
            <origin xyz="0 0.27513766769836867 0" rpy="0 0 0"/>
            <mass value="1" />
            <inertia ixx="100" ixy="0" ixz="0" iyy="100" iyz="0" izz="100" />
        </inertial>
        <visual>
            <origin xyz="0 0.27513766769836867 0" rpy="0 0 0"/>
            <geometry>
                <box size="0.5890285413646168 0.5502753353967373 0.5890737761080749" />
            </geometry>
            <material name="Green">
                <color rgba="0.0 1.0 0.0 1.0"/>
            </material>
        </visual>
        <collision>
            <origin xyz="0 0.27513766769836867 0" rpy="0 0 0"/>
            <geometry>
                <box size="0.5890285413646168 0.5502753353967373 0.5890737761080749" />
            </geometry>
        </collision>
    </link>
    <link name="Body2.1.0">
        <inertial>
            <origin xyz="0 -0.16523312333717766 0" rpy="0 0 0"/>
            <mass value="1" />
            <inertia ixx="100" ixy="0" ixz="0" iyy="100" iyz="0" izz="100" />
        </inertial>
        <visual>
            <origin xyz="0 -0.16523312333717766 0" rpy="0 0 0"/>
            <geometry>
                <box size="0.34469819693315795 0.3304662466743553 0.615185879305858" />
            </geometry>
            <material name="Green">
                <color rgba="0.0 1.0 0.0 1.0"/>
            </material>
        </visual>
        <collision>
            <origin xyz="0 -0.16523312333717766 0" rpy="0 0 0"/>
            <geometry>
                <box size="0.34469819693315795 0.3304662466743553 0.615185879305858" />
            </geometry>
        </collision>
    </link>
    <link name="Body2.1.1">
        <inertial>
            <origin xyz="0 0 -0.32946946204368016" rpy="0 0 0"/>
            <mass value="1" />
            <inertia ixx="100" ixy="0" ixz="0" iyy="100" iyz="0" izz="100" />
        </inertial>
        <visual>
            <origin xyz="0 0 -0.32946946204368016" rpy="0 0 0"/>
            <geometry>
                <box size="0.45172566385223645 0.28467655746239356 0.6589389240873603" />
            </geometry>
            <material name="Blue">
                <color rgba="0.0 0.0 1.0 1.0"/>
            </material>
        </visual>
        <collision>
            <origin xyz="0 0 -0.32946946204368016" rpy="0 0 0"/>
            <geometry>
                <box size="0.45172566385223645 0.28467655746239356 0.6589389240873603" />
            </geometry>
        </collision>
    </link>
    <link name="Body2.2.0">
        <inertial>
            <origin xyz="0 0.14432801458459021 0" rpy="0 0 0"/>
            <mass value="1" />
            <inertia ixx="100" ixy="0" ixz="0" iyy="100" iyz="0" izz="100" />
        </inertial>
        <visual>
            <origin xyz="0 0.14432801458459021 0" rpy="0 0 0"/>
            <geometry>
                <box size="0.5210366255494656 0.28865602916918043 0.6454762280375055" />
            </geometry>
            <material name="Green">
                <color rgba="0.0 1.0 0.0 1.0"/>
            </material>
        </visual>
        <collision>
            <origin xyz="0 0.14432801458459021 0" rpy="0 0 0"/>
            <geometry>
                <box size="0.5210366255494656 0.28865602916918043 0.6454762280375055" />
            </geometry>
        </collision>
    </link>
    <link name="Body2.2.1">
        <inertial>
            <origin xyz="0 0.23672702244587485 0" rpy="0 0 0"/>
            <mass value="1" />
            <inertia ixx="100" ixy="0" ixz="0" iyy="100" iyz="0" izz="100" />
        </inertial>
        <visual>
            <origin xyz="0 0.23672702244587485 0" rpy="0 0 0"/>
            <geometry>
                <box size="0.6808435304447359 0.4734540448917497 0.7011706968660203" />
            </geometry>
            <material name="Blue">
                <color rgba="0.0 0.0 1.0 1.0"/>
            </material>
        </visual>
        <collision>
            <origin xyz="0 0.23672702244587485 0" rpy="0 0 0"/>
            <geometry>
                <box size="0.6808435304447359 0.4734540448917497 0.7011706968660203" />
            </geometry>
        </collision>
    </link>
    <link name="Body2.2.2">
        <inertial>
            <origin xyz="0 0 -0.3118584633645128" rpy="0 0 0"/>
            <mass value="1" />
            <inertia ixx="100" ixy="0" ixz="0" iyy="100" iyz="0" izz="100" />
        </inertial>
        <visual>
            <origin xyz="0 0 -0.3118584633645128" rpy="0 0 0"/>
            <geometry>
                <box size="0.47114422193769095 0.6600458913159986 0.6237169267290256" />
            </geometry>
            <material name="Blue">
                <color rgba="0.0 0.0 1.0 1.0"/>
            </material>
        </visual>
        <collision>
            <origin xyz="0 0 -0.3118584633645128" rpy="0 0 0"/>
            <geometry>
                <box size="0.47114422193769095 0.6600458913159986 0.6237169267290256" />
            </geometry>
        </collision>
    </link>
    <link name="Body3.2.0">
        <inertial>
            <origin xyz="0 0.3325224310428727 0" rpy="0 0 0"/>
            <mass value="1" />
            <inertia ixx="100" ixy="0" ixz="0" iyy="100" iyz="0" izz="100" />
        </inertial>
        <visual>
            <origin xyz="0 0.3325224310428727 0" rpy="0 0 0"/>
            <geometry>
                <box size="0.7435950875590893 0.6650448620857454 0.594203182736088" />
            </geometry>
            <material name="Green">
                <color rgba="0.0 1.0 0.0 1.0"/>
            </material>
        </visual>
        <collision>
            <origin xyz="0 0.3325224310428727 0" rpy="0 0 0"/>
            <geometry>
                <box size="0.7435950875590893 0.6650448620857454 0.594203182736088" />
            </geometry>
        </collision>
    </link>
    <link name="Body3.2.1">
        <inertial>
            <origin xyz="0 0.3593809254833046 0" rpy="0 0 0"/>
            <mass value="1" />
            <inertia ixx="100" ixy="0" ixz="0" iyy="100" iyz="0" izz="100" />
        </inertial>
        <visual>
            <origin xyz="0 0.3593809254833046 0" rpy="0 0 0"/>
            <geometry>
                <box size="0.25923082038015055 0.7187618509666092 0.6073014412411711" />
            </geometry>
            <material name="Green">
                <color rgba="0.0 1.0 0.0 1.0"/>
            </material>
        </visual>
        <collision>
            <origin xyz="0 0.3593809254833046 0" rpy="0 0 0"/>
            <geometry>
                <box size="0.25923082038015055 0.7187618509666092 0.6073014412411711" />
            </geometry>
        </collision>
    </link>
    <link name="Body4.2.0">
        <inertial>
            <origin xyz="0 0.3348623442093101 0" rpy="0 0 0"/>
            <mass value="1" />
            <inertia ixx="100" ixy="0" ixz="0" iyy="100" iyz="0" izz="100" />
        </inertial>
        <visual>
            <origin xyz="0 0.3348623442093101 0" rpy="0 0 0"/>
            <geometry>
                <box size="0.7238463091261259 0.6697246884186202 0.5311782231416993" />
            </geometry>
            <material name="Green">
                <color rgba="0.0 1.0 0.0 1.0"/>
            </material>
        </visual>
        <collision>
            <origin xyz="0 0.3348623442093101 0" rpy="0 0 0"/>
            <geometry>
                <box size="0.7238463091261259 0.6697246884186202 0.5311782231416993" />
            </geometry>
        </collision>
    </link>
    <link name="Body4.2.1">
        <inertial>
            <origin xyz="0 0 -0.34443699581090037" rpy="0 0 0"/>
            <mass value="1" />
            <inertia ixx="100" ixy="0" ixz="0" iyy="100" iyz="0" izz="100" />
        </inertial>
        <visual>
            <origin xyz="0 0 -0.34443699581090037" rpy="0 0 0"/>
            <geometry>
                <box size="0.5922496661074281 0.6910973475713156 0.6888739916218007" />
            </geometry>
            <material name="Green">
                <color rgba="0.0 1.0 0.0 1.0"/>
            </material>
        </visual>
        <collision>
            <origin xyz="0 0 -0.34443699581090037" rpy="0 0 0"/>
            <geometry>
                <box size="0.5922496661074281 0.6910973475713156 0.6888739916218007" />
            </geometry>
        </collision>
    </link>
    <joint name="Body1.0.0_Body2.0.0" type="revolute">
       <parent link="Body1.0.0"/>
       <child  link="Body2.0.0"/>
       <origin rpy="0 0 0" xyz="0.5382376225336805 0 3" />
       <axis xyz="0 0 1"/>
       <limit effort="0.0" lower="-3.14159" upper="3.14159" velocity="0.0"/>
    </joint>
    <joint name="Body2.0.0_Body3.0.0" type="revolute">
       <parent link="Body2.0.0"/>
       <child  link="Body3.0.0"/>
       <origin rpy="0 0 0" xyz="1.0310979123709685 0 0" />
       <axis xyz="1 0 0"/>
       <limit effort="0.0" lower="-3.14159" upper="3.14159" velocity="0.0"/>
    </joint>
    <joint name="Body3.0.0_Body4.0.0" type="revolute">
       <parent link="Body3.0.0"/>
       <child  link="Body4.0.0"/>
       <origin rpy="0 0 0" xyz="1.2408705368534863 0 0" />
       <axis xyz="0 1 0"/>
       <limit effort="0.0" lower="-3.14159" upper="3.14159" velocity="0.0"/>
    </joint>
    <joint name="Body1.0.0_Body1.2.0" type="revolute">
       <parent link="Body1.0.0"/>
       <child  link="Body1.2.0"/>
       <origin rpy="0 0 0" xyz="0 0.40903005868983594 3" />
       <axis xyz="0 1 0"/>
       <limit effort="0.0" lower="-3.14159" upper="3.14159" velocity="0.0"/>
    </joint>
    <joint name="Body2.0.0_Body2.1.0" type="revolute">
       <parent link="Body2.0.0"/>
       <child  link="Body2.1.0"/>
       <origin rpy="0 0 0" xyz="0.5155489561854842 -0.5075039893267086 0" />
       <axis xyz="1 0 0"/>
       <limit effort="0.0" lower="-3.14159" upper="3.14159" velocity="0.0"/>
    </joint>
    <joint name="Body2.1.0_Body2.1.1" type="revolute">
       <parent link="Body2.1.0"/>
       <child  link="Body2.1.1"/>
       <origin rpy="0 0 0" xyz="0 -0.16523312333717766 -0.307592939652929" />
       <axis xyz="0 0 1"/>
       <limit effort="0.0" lower="-3.14159" upper="3.14159" velocity="0.0"/>
    </joint>
    <joint name="Body2.0.0_Body2.2.0" type="revolute">
       <parent link="Body2.0.0"/>
       <child  link="Body2.2.0"/>
       <origin rpy="0 0 0" xyz="0.5155489561854842 0.5075039893267086 0" />
       <axis xyz="0 1 0"/>
       <limit effort="0.0" lower="-3.14159" upper="3.14159" velocity="0.0"/>
    </joint>
    <joint name="Body2.2.0_Body2.2.1" type="revolute">
       <parent link="Body2.2.0"/>
       <child  link="Body2.2.1"/>
       <origin rpy="0 0 0" xyz="0 0.28865602916918043 0" />
       <axis xyz="1 0 0"/>
       <limit effort="0.0" lower="-3.14159" upper="3.14159" velocity="0.0"/>
    </joint>
    <joint name="Body2.2.1_Body2.2.2" type="revolute">
       <parent link="Body2.2.1"/>
       <child  link="Body2.2.2"/>
       <origin rpy="0 0 0" xyz="0 0.23672702244587485 -0.35058534843301015" />
       <axis xyz="1 0 0"/>
       <limit effort="0.0" lower="-3.14159" upper="3.14159" velocity="0.0"/>
    </joint>
    <joint name="Body3.0.0_Body3.2.0" type="revolute">
       <parent link="Body3.0.0"/>
       <child  link="Body3.2.0"/>
       <origin rpy="0 0 0" xyz="0.6204352684267431 0.6044643641216121 0" />
       <axis xyz="0 1 0"/>
       <limit effort="0.0" lower="-3.14159" upper="3.14159" velocity="0.0"/>
    </joint>
    <joint name="Body3.2.0_Body3.2.1" type="revolute">
       <parent link="Body3.2.0"/>
       <child  link="Body3.2.1"/>
       <origin rpy="0 0 0" xyz="0 0.6650448620857454 0" />
       <axis xyz="1 0 0"/>
       <limit effort="0.0" lower="-3.14159" upper="3.14159" velocity="0.0"/>
    </joint>
    <joint name="Body4.0.0_Body4.2.0" type="revolute">
       <parent link="Body4.0.0"/>
       <child  link="Body4.2.0"/>
       <origin rpy="0 0 0" xyz="0.5685982130083045 0.4426535949187196 0" />
       <axis xyz="1 0 0"/>
       <limit effort="0.0" lower="-3.14159" upper="3.14159" velocity="0.0"/>
    </joint>
    <joint name="Body4.2.0_Body4.2.1" type="revolute">
       <parent link="Body4.2.0"/>
       <child  link="Body4.2.1"/>
       <origin rpy="0 0 0" xyz="0 0.3348623442093101 -0.26558911157084963" />
       <axis xyz="0 1 0"/>
       <limit effort="0.0" lower="-3.14159" upper="3.14159" velocity="0.0"/>
    </joint>
</robot>