<robot name = "robot">
    <link name="Body1.0.0">
        <inertial>
            <origin xyz="0 0 3" rpy="0 0 0"/>
            <mass value="1" />
            <inertia ixx="100" ixy="0" ixz="0" iyy="100" iyz="0" izz="100" />
        </inertial>
        <visual>
            <origin xyz="0 0 3" rpy="0 0 0"/>
            <geometry>
                <box size="1.1628982431806907 1.091542513351635 0.5703946900806762" />
            </geometry>
            <material name="Blue">
                <color rgba="0.0 0.0 1.0 1.0"/>
            </material>
        </visual>
        <collision>
            <origin xyz="0 0 3" rpy="0 0 0"/>
            <geometry>
                <box size="1.1628982431806907 1.091542513351635 0.5703946900806762" />
            </geometry>
        </collision>
    </link>
    <link name="Body2.0.0">
        <inertial>
            <origin xyz="0.5035434345652507 0 0" rpy="0 0 0"/>
            <mass value="1" />
            <inertia ixx="100" ixy="0" ixz="0" iyy="100" iyz="0" izz="100" />
        </inertial>
        <visual>
            <origin xyz="0.5035434345652507 0 0" rpy="0 0 0"/>
            <geometry>
                <box size="1.0070868691305015 1.1268238279399023 0.8245753009287901" />
            </geometry>
            <material name="Green">
                <color rgba="0.0 1.0 0.0 1.0"/>
            </material>
        </visual>
        <collision>
            <origin xyz="0.5035434345652507 0 0" rpy="0 0 0"/>
            <geometry>
                <box size="1.0070868691305015 1.1268238279399023 0.8245753009287901" />
            </geometry>
        </collision>
    </link>
    <link name="Body1.1.0">
        <inertial>
            <origin xyz="0 -0.1915826401143149 0" rpy="0 0 0"/>
            <mass value="1" />
            <inertia ixx="100" ixy="0" ixz="0" iyy="100" iyz="0" izz="100" />
        </inertial>
        <visual>
            <origin xyz="0 -0.1915826401143149 0" rpy="0 0 0"/>
            <geometry>
                <box size="0.5979164333842217 0.3831652802286298 0.7004565917491209" />
            </geometry>
            <material name="Green">
                <color rgba="0.0 1.0 0.0 1.0"/>
            </material>
        </visual>
        <collision>
            <origin xyz="0 -0.1915826401143149 0" rpy="0 0 0"/>
            <geometry>
                <box size="0.5979164333842217 0.3831652802286298 0.7004565917491209" />
            </geometry>
        </collision>
    </link>
    <link name="Body1.1.1">
        <inertial>
            <origin xyz="0 0 -0.2538237478791942" rpy="0 0 0"/>
            <mass value="1" />
            <inertia ixx="100" ixy="0" ixz="0" iyy="100" iyz="0" izz="100" />
        </inertial>
        <visual>
            <origin xyz="0 0 -0.2538237478791942" rpy="0 0 0"/>
            <geometry>
                <box size="0.7226353477769611 0.7007137288057418 0.5076474957583884" />
            </geometry>
            <material name="Blue">
                <color rgba="0.0 0.0 1.0 1.0"/>
            </material>
        </visual>
        <collision>
            <origin xyz="0 0 -0.2538237478791942" rpy="0 0 0"/>
            <geometry>
                <box size="0.7226353477769611 0.7007137288057418 0.5076474957583884" />
            </geometry>
        </collision>
    </link>
    <link name="Body1.1.2">
        <inertial>
            <origin xyz="0 0 -0.27707492464132666" rpy="0 0 0"/>
            <mass value="1" />
            <inertia ixx="100" ixy="0" ixz="0" iyy="100" iyz="0" izz="100" />
        </inertial>
        <visual>
            <origin xyz="0 0 -0.27707492464132666" rpy="0 0 0"/>
            <geometry>
                <box size="0.7195745813892553 0.4406021188441062 0.5541498492826533" />
            </geometry>
            <material name="Green">
                <color rgba="0.0 1.0 0.0 1.0"/>
            </material>
        </visual>
        <collision>
            <origin xyz="0 0 -0.27707492464132666" rpy="0 0 0"/>
            <geometry>
                <box size="0.7195745813892553 0.4406021188441062 0.5541498492826533" />
            </geometry>
        </collision>
    </link>
    <link name="Body1.1.3">
        <inertial>
            <origin xyz="0 0 -0.3673958773685733" rpy="0 0 0"/>
            <mass value="1" />
            <inertia ixx="100" ixy="0" ixz="0" iyy="100" iyz="0" izz="100" />
        </inertial>
        <visual>
            <origin xyz="0 0 -0.3673958773685733" rpy="0 0 0"/>
            <geometry>
                <box size="0.5138147071811991 0.6318504975657447 0.7347917547371466" />
            </geometry>
            <material name="Green">
                <color rgba="0.0 1.0 0.0 1.0"/>
            </material>
        </visual>
        <collision>
            <origin xyz="0 0 -0.3673958773685733" rpy="0 0 0"/>
            <geometry>
                <box size="0.5138147071811991 0.6318504975657447 0.7347917547371466" />
            </geometry>
        </collision>
    </link>
    <link name="Body2.1.0">
        <inertial>
            <origin xyz="0 -0.2942121349624936 0" rpy="0 0 0"/>
            <mass value="1" />
            <inertia ixx="100" ixy="0" ixz="0" iyy="100" iyz="0" izz="100" />
        </inertial>
        <visual>
            <origin xyz="0 -0.2942121349624936 0" rpy="0 0 0"/>
            <geometry>
                <box size="0.42285020735437623 0.5884242699249872 0.6902369343854551" />
            </geometry>
            <material name="Green">
                <color rgba="0.0 1.0 0.0 1.0"/>
            </material>
        </visual>
        <collision>
            <origin xyz="0 -0.2942121349624936 0" rpy="0 0 0"/>
            <geometry>
                <box size="0.42285020735437623 0.5884242699249872 0.6902369343854551" />
            </geometry>
        </collision>
    </link>
    <link name="Body2.1.1">
        <inertial>
            <origin xyz="0 0 -0.36453372943816176" rpy="0 0 0"/>
            <mass value="1" />
            <inertia ixx="100" ixy="0" ixz="0" iyy="100" iyz="0" izz="100" />
        </inertial>
        <visual>
            <origin xyz="0 0 -0.36453372943816176" rpy="0 0 0"/>
            <geometry>
                <box size="0.713253311892933 0.45808996944717306 0.7290674588763235" />
            </geometry>
            <material name="Blue">
                <color rgba="0.0 0.0 1.0 1.0"/>
            </material>
        </visual>
        <collision>
            <origin xyz="0 0 -0.36453372943816176" rpy="0 0 0"/>
            <geometry>
                <box size="0.713253311892933 0.45808996944717306 0.7290674588763235" />
            </geometry>
        </collision>
    </link>
    <joint name="Body1.0.0_Body2.0.0" type="revolute">
       <parent link="Body1.0.0"/>
       <child  link="Body2.0.0"/>
       <origin rpy="0 0 0" xyz="0.5814491215903453 0 3" />
       <axis xyz="0 0 1"/>
       <limit effort="0.0" lower="-3.14159" upper="3.14159" velocity="0.0"/>
    </joint>
    <joint name="Body1.0.0_Body1.1.0" type="revolute">
       <parent link="Body1.0.0"/>
       <child  link="Body1.1.0"/>
       <origin rpy="0 0 0" xyz="0 -0.5457712566758175 3" />
       <axis xyz="0 0 1"/>
       <limit effort="0.0" lower="-3.14159" upper="3.14159" velocity="0.0"/>
    </joint>
    <joint name="Body1.1.0_Body1.1.1" type="revolute">
       <parent link="Body1.1.0"/>
       <child  link="Body1.1.1"/>
       <origin rpy="0 0 0" xyz="0 -0.1915826401143149 -0.35022829587456045" />
       <axis xyz="1 0 0"/>
       <limit effort="0.0" lower="-3.14159" upper="3.14159" velocity="0.0"/>
    </joint>
    <joint name="Body1.1.1_Body1.1.2" type="revolute">
       <parent link="Body1.1.1"/>
       <child  link="Body1.1.2"/>
       <origin rpy="0 0 0" xyz="0 0 -0.5076474957583884" />
       <axis xyz="0 1 0"/>
       <limit effort="0.0" lower="-3.14159" upper="3.14159" velocity="0.0"/>
    </joint>
    <joint name="Body1.1.2_Body1.1.3" type="revolute">
       <parent link="Body1.1.2"/>
       <child  link="Body1.1.3"/>
       <origin rpy="0 0 0" xyz="0 0 -0.5541498492826533" />
       <axis xyz="0 0 1"/>
       <limit effort="0.0" lower="-3.14159" upper="3.14159" velocity="0.0"/>
    </joint>
    <joint name="Body2.0.0_Body2.1.0" type="revolute">
       <parent link="Body2.0.0"/>
       <child  link="Body2.1.0"/>
       <origin rpy="0 0 0" xyz="0.5035434345652507 -0.5634119139699512 0" />
       <axis xyz="1 0 0"/>
       <limit effort="0.0" lower="-3.14159" upper="3.14159" velocity="0.0"/>
    </joint>
    <joint name="Body2.1.0_Body2.1.1" type="revolute">
       <parent link="Body2.1.0"/>
       <child  link="Body2.1.1"/>
       <origin rpy="0 0 0" xyz="0 -0.2942121349624936 -0.34511846719272754" />
       <axis xyz="0 0 1"/>
       <limit effort="0.0" lower="-3.14159" upper="3.14159" velocity="0.0"/>
    </joint>
</robot>