<robot name = "robot">
    <link name="Body1.0.0">
        <inertial>
            <origin xyz="0 0 3" rpy="0 0 0"/>
            <mass value="1" />
            <inertia ixx="100" ixy="0" ixz="0" iyy="100" iyz="0" izz="100" />
        </inertial>
        <visual>
            <origin xyz="0 0 3" rpy="0 0 0"/>
            <geometry>
                <box size="1.1841778204887097 0.6975622570955428 0.994111990181519" />
            </geometry>
            <material name="Green">
                <color rgba="0.0 1.0 0.0 1.0"/>
            </material>
        </visual>
        <collision>
            <origin xyz="0 0 3" rpy="0 0 0"/>
            <geometry>
                <box size="1.1841778204887097 0.6975622570955428 0.994111990181519" />
            </geometry>
        </collision>
    </link>
    <link name="Body2.0.0">
        <inertial>
            <origin xyz="0.5809375391780194 0 0" rpy="0 0 0"/>
            <mass value="1" />
            <inertia ixx="100" ixy="0" ixz="0" iyy="100" iyz="0" izz="100" />
        </inertial>
        <visual>
            <origin xyz="0.5809375391780194 0 0" rpy="0 0 0"/>
            <geometry>
                <box size="1.1618750783560388 0.6533641200625381 0.6722789126042608" />
            </geometry>
            <material name="Blue">
                <color rgba="0.0 0.0 1.0 1.0"/>
            </material>
        </visual>
        <collision>
            <origin xyz="0.5809375391780194 0 0" rpy="0 0 0"/>
            <geometry>
                <box size="1.1618750783560388 0.6533641200625381 0.6722789126042608" />
            </geometry>
        </collision>
    </link>
    <link name="Body1.1.0">
        <inertial>
            <origin xyz="0 -0.160207819544887 0" rpy="0 0 0"/>
            <mass value="1" />
            <inertia ixx="100" ixy="0" ixz="0" iyy="100" iyz="0" izz="100" />
        </inertial>
        <visual>
            <origin xyz="0 -0.160207819544887 0" rpy="0 0 0"/>
            <geometry>
                <box size="0.7304301864596485 0.320415639089774 0.7232136118169956" />
            </geometry>
            <material name="Blue">
                <color rgba="0.0 0.0 1.0 1.0"/>
            </material>
        </visual>
        <collision>
            <origin xyz="0 -0.160207819544887 0" rpy="0 0 0"/>
            <geometry>
                <box size="0.7304301864596485 0.320415639089774 0.7232136118169956" />
            </geometry>
        </collision>
    </link>
    <link name="Body1.1.1">
        <inertial>
            <origin xyz="0 -0.36582894592521575 0" rpy="0 0 0"/>
            <mass value="1" />
            <inertia ixx="100" ixy="0" ixz="0" iyy="100" iyz="0" izz="100" />
        </inertial>
        <visual>
            <origin xyz="0 -0.36582894592521575 0" rpy="0 0 0"/>
            <geometry>
                <box size="0.5631608195963986 0.7316578918504315 0.5527084980217125" />
            </geometry>
            <material name="Green">
                <color rgba="0.0 1.0 0.0 1.0"/>
            </material>
        </visual>
        <collision>
            <origin xyz="0 -0.36582894592521575 0" rpy="0 0 0"/>
            <geometry>
                <box size="0.5631608195963986 0.7316578918504315 0.5527084980217125" />
            </geometry>
        </collision>
    </link>
    <link name="Body1.1.2">
        <inertial>
            <origin xyz="0 0 -0.2700527262468667" rpy="0 0 0"/>
            <mass value="1" />
            <inertia ixx="100" ixy="0" ixz="0" iyy="100" iyz="0" izz="100" />
        </inertial>
        <visual>
            <origin xyz="0 0 -0.2700527262468667" rpy="0 0 0"/>
            <geometry>
                <box size="0.7005760214936961 0.6590090966787152 0.5401054524937334" />
            </geometry>
            <material name="Blue">
                <color rgba="0.0 0.0 1.0 1.0"/>
            </material>
        </visual>
        <collision>
            <origin xyz="0 0 -0.2700527262468667" rpy="0 0 0"/>
            <geometry>
                <box size="0.7005760214936961 0.6590090966787152 0.5401054524937334" />
            </geometry>
        </collision>
    </link>
    <link name="Body1.2.0">
        <inertial>
            <origin xyz="0 0.2756905395454097 0" rpy="0 0 0"/>
            <mass value="1" />
            <inertia ixx="100" ixy="0" ixz="0" iyy="100" iyz="0" izz="100" />
        </inertial>
        <visual>
            <origin xyz="0 0.2756905395454097 0" rpy="0 0 0"/>
            <geometry>
                <box size="0.3403237089725028 0.5513810790908193 0.5369011233998475" />
            </geometry>
            <material name="Blue">
                <color rgba="0.0 0.0 1.0 1.0"/>
            </material>
        </visual>
        <collision>
            <origin xyz="0 0.2756905395454097 0" rpy="0 0 0"/>
            <geometry>
                <box size="0.3403237089725028 0.5513810790908193 0.5369011233998475" />
            </geometry>
        </collision>
    </link>
    <link name="Body1.2.1">
        <inertial>
            <origin xyz="0 0 -0.2532668522687413" rpy="0 0 0"/>
            <mass value="1" />
            <inertia ixx="100" ixy="0" ixz="0" iyy="100" iyz="0" izz="100" />
        </inertial>
        <visual>
            <origin xyz="0 0 -0.2532668522687413" rpy="0 0 0"/>
            <geometry>
                <box size="0.33127009195328 0.33350729510625715 0.5065337045374826" />
            </geometry>
            <material name="Blue">
                <color rgba="0.0 0.0 1.0 1.0"/>
            </material>
        </visual>
        <collision>
            <origin xyz="0 0 -0.2532668522687413" rpy="0 0 0"/>
            <geometry>
                <box size="0.33127009195328 0.33350729510625715 0.5065337045374826" />
            </geometry>
        </collision>
    </link>
    <link name="Body1.2.2">
        <inertial>
            <origin xyz="0 0 -0.3652895231753057" rpy="0 0 0"/>
            <mass value="1" />
            <inertia ixx="100" ixy="0" ixz="0" iyy="100" iyz="0" izz="100" />
        </inertial>
        <visual>
            <origin xyz="0 0 -0.3652895231753057" rpy="0 0 0"/>
            <geometry>
                <box size="0.7350711950964945 0.6497015529789023 0.7305790463506114" />
            </geometry>
            <material name="Green">
                <color rgba="0.0 1.0 0.0 1.0"/>
            </material>
        </visual>
        <collision>
            <origin xyz="0 0 -0.3652895231753057" rpy="0 0 0"/>
            <geometry>
                <box size="0.7350711950964945 0.6497015529789023 0.7305790463506114" />
            </geometry>
        </collision>
    </link>
    <link name="Body2.1.0">
        <inertial>
            <origin xyz="0 -0.3142154067168459 0" rpy="0 0 0"/>
            <mass value="1" />
            <inertia ixx="100" ixy="0" ixz="0" iyy="100" iyz="0" izz="100" />
        </inertial>
        <visual>
            <origin xyz="0 -0.3142154067168459 0" rpy="0 0 0"/>
            <geometry>
                <box size="0.5619362129045711 0.6284308134336918 0.5131144162436951" />
            </geometry>
            <material name="Green">
                <color rgba="0.0 1.0 0.0 1.0"/>
            </material>
        </visual>
        <collision>
            <origin xyz="0 -0.3142154067168459 0" rpy="0 0 0"/>
            <geometry>
                <box size="0.5619362129045711 0.6284308134336918 0.5131144162436951" />
            </geometry>
        </collision>
    </link>
    <link name="Body2.2.0">
        <inertial>
            <origin xyz="0 0.31873889999179106 0" rpy="0 0 0"/>
            <mass value="1" />
            <inertia ixx="100" ixy="0" ixz="0" iyy="100" iyz="0" izz="100" />
        </inertial>
        <visual>
            <origin xyz="0 0.31873889999179106 0" rpy="0 0 0"/>
            <geometry>
                <box size="0.6086520389424095 0.6374777999835821 0.6267782593405681" />
            </geometry>
            <material name="Green">
                <color rgba="0.0 1.0 0.0 1.0"/>
            </material>
        </visual>
        <collision>
            <origin xyz="0 0.31873889999179106 0" rpy="0 0 0"/>
            <geometry>
                <box size="0.6086520389424095 0.6374777999835821 0.6267782593405681" />
            </geometry>
        </collision>
    </link>
    <link name="Body2.2.1">
        <inertial>
            <origin xyz="0 0.20967882597479826 0" rpy="0 0 0"/>
            <mass value="1" />
            <inertia ixx="100" ixy="0" ixz="0" iyy="100" iyz="0" izz="100" />
        </inertial>
        <visual>
            <origin xyz="0 0.20967882597479826 0" rpy="0 0 0"/>
            <geometry>
                <box size="0.5948803893863207 0.4193576519495965 0.6704532622234305" />
            </geometry>
            <material name="Blue">
                <color rgba="0.0 0.0 1.0 1.0"/>
            </material>
        </visual>
        <collision>
            <origin xyz="0 0.20967882597479826 0" rpy="0 0 0"/>
            <geometry>
                <box size="0.5948803893863207 0.4193576519495965 0.6704532622234305" />
            </geometry>
        </collision>
    </link>
    <link name="Body2.2.2">
        <inertial>
            <origin xyz="0 0.22543405697029384 0" rpy="0 0 0"/>
            <mass value="1" />
            <inertia ixx="100" ixy="0" ixz="0" iyy="100" iyz="0" izz="100" />
        </inertial>
        <visual>
            <origin xyz="0 0.22543405697029384 0" rpy="0 0 0"/>
            <geometry>
                <box size="0.7492226231230941 0.4508681139405877 0.5154858041812078" />
            </geometry>
            <material name="Green">
                <color rgba="0.0 1.0 0.0 1.0"/>
            </material>
        </visual>
        <collision>
            <origin xyz="0 0.22543405697029384 0" rpy="0 0 0"/>
            <geometry>
                <box size="0.7492226231230941 0.4508681139405877 0.5154858041812078" />
            </geometry>
        </collision>
    </link>
    <joint name="Body1.0.0_Body2.0.0" type="revolute">
       <parent link="Body1.0.0"/>
       <child  link="Body2.0.0"/>
       <origin rpy="0 0 0" xyz="0.5920889102443548 0 3" />
       <axis xyz="0 0 1"/>
       <limit effort="0.0" lower="-3.14159" upper="3.14159" velocity="0.0"/>
    </joint>
    <joint name="Body1.0.0_Body1.1.0" type="revolute">
       <parent link="Body1.0.0"/>
       <child  link="Body1.1.0"/>
       <origin rpy="0 0 0" xyz="0 -0.3487811285477714 3" />
       <axis xyz="0 1 0"/>
       <limit effort="0.0" lower="-3.14159" upper="3.14159" velocity="0.0"/>
    </joint>
    <joint name="Body1.1.0_Body1.1.1" type="revolute">
       <parent link="Body1.1.0"/>
       <child  link="Body1.1.1"/>
       <origin rpy="0 0 0" xyz="0 -0.320415639089774 0" />
       <axis xyz="1 0 0"/>
       <limit effort="0.0" lower="-3.14159" upper="3.14159" velocity="0.0"/>
    </joint>
    <joint name="Body1.1.1_Body1.1.2" type="revolute">
       <parent link="Body1.1.1"/>
       <child  link="Body1.1.2"/>
       <origin rpy="0 0 0" xyz="0 -0.36582894592521575 -0.27635424901085626" />
       <axis xyz="0 0 1"/>
       <limit effort="0.0" lower="-3.14159" upper="3.14159" velocity="0.0"/>
    </joint>
    <joint name="Body1.0.0_Body1.2.0" type="revolute">
       <parent link="Body1.0.0"/>
       <child  link="Body1.2.0"/>
       <origin rpy="0 0 0" xyz="0 0.3487811285477714 3" />
       <axis xyz="0 0 1"/>
       <limit effort="0.0" lower="-3.14159" upper="3.14159" velocity="0.0"/>
    </joint>
    <joint name="Body1.2.0_Body1.2.1" type="revolute">
       <parent link="Body1.2.0"/>
       <child  link="Body1.2.1"/>
       <origin rpy="0 0 0" xyz="0 0.2756905395454097 -0.26845056169992376" />
       <axis xyz="0 0 1"/>
       <limit effort="0.0" lower="-3.14159" upper="3.14159" velocity="0.0"/>
    </joint>
    <joint name="Body1.2.1_Body1.2.2" type="revolute">
       <parent link="Body1.2.1"/>
       <child  link="Body1.2.2"/>
       <origin rpy="0 0 0" xyz="0 0 -0.5065337045374826" />
       <axis xyz="0 1 0"/>
       <limit effort="0.0" lower="-3.14159" upper="3.14159" velocity="0.0"/>
    </joint>
    <joint name="Body2.0.0_Body2.1.0" type="revolute">
       <parent link="Body2.0.0"/>
       <child  link="Body2.1.0"/>
       <origin rpy="0 0 0" xyz="0.5809375391780194 -0.32668206003126904 0" />
       <axis xyz="0 1 0"/>
       <limit effort="0.0" lower="-3.14159" upper="3.14159" velocity="0.0"/>
    </joint>
    <joint name="Body2.0.0_Body2.2.0" type="revolute">
       <parent link="Body2.0.0"/>
       <child  link="Body2.2.0"/>
       <origin rpy="0 0 0" xyz="0.5809375391780194 0.32668206003126904 0" />
       <axis xyz="0 1 0"/>
       <limit effort="0.0" lower="-3.14159" upper="3.14159" velocity="0.0"/>
    </joint>
    <joint name="Body2.2.0_Body2.2.1" type="revolute">
       <parent link="Body2.2.0"/>
       <child  link="Body2.2.1"/>
       <origin rpy="0 0 0" xyz="0 0.6374777999835821 0" />
       <axis xyz="0 0 1"/>
       <limit effort="0.0" lower="-3.14159" upper="3.14159" velocity="0.0"/>
    </joint>
    <joint name="Body2.2.1_Body2.2.2" type="revolute">
       <parent link="Body2.2.1"/>
       <child  link="Body2.2.2"/>
       <origin rpy="0 0 0" xyz="0 0.4193576519495965 0" />
       <axis xyz="0 0 1"/>
       <limit effort="0.0" lower="-3.14159" upper="3.14159" velocity="0.0"/>
    </joint>
</robot>